<?xml version="1.0" encoding="utf-8"?>
<!-- This URDF was create by Shen Tan shiinatan1024@gmail.com -->
<robot
  name="moper_robot">

  <material name="DarkGrey">
  <color rgba="0.35 0.35 0.35 1.0"/>
  </material>

  <material name="PlasticBlack">
  <color rgba="0.23 0.23 0.23 1.0"/>
  </material>

  <material name="Aluminium">
  <color rgba="0.79 0.79 0.79 1.0"/>
  </material>

<!--                                            -->
<!-- Chassis base (wheeltec omnibeering chassis)-->
<!--                                            -->
  <link
    name="chassis_base_link">
    <inertial>
      <origin
        xyz="0.00 0.00 0.043"
        rpy="0 0 0" />
      <mass
        value="3.4" />
      <inertia
        ixx="0.0211328571278065"
        ixy="0.0"
        ixz="0.0"
        iyy="0.0209049304668755"
        iyz="0.0"
        izz="0.0408049369808656" />
    </inertial>
    <visual>
      <origin
        xyz="0 0 0"
        rpy="0 0 0" />
      <geometry>
        <mesh
          filename="meshes/chassis/chassis_base_link.STL" />
      </geometry>
      <material name="Aluminium"/>
    </visual>
    <collision>
      <origin
        xyz="0 0 0"
        rpy="0 0 0" />
      <geometry>
        <mesh
          filename="meshes/chassis/chassis_base_link.STL" />
      </geometry>
    </collision>
  </link>


  <link
    name="chassis_wheel1_link">
    <inertial>
      <origin
        xyz="0.0 0.0 0.0"
        rpy="0 0 0" />
      <mass
        value="0.225" />
      <inertia
        ixx="0.000250170315003475"
        ixy="0.0"
        ixz="0.0"
        iyy="0.00045368203804365"
        iyz="0.0"
        izz="0.000250170177147773" />
    </inertial>
    <visual>
      <origin
        xyz="0 0 0"
        rpy="0 0 0" />
      <geometry>
        <mesh
          filename="meshes/chassis/chassis_wheel1_link.STL" />
      </geometry>
      <material
        name="DarkGrey">
      </material>
    </visual>
    <collision>
      <origin
        xyz="0 0 0"
        rpy="0 0 0" />
      <geometry>
        <mesh
          filename="meshes/chassis/chassis_wheel1_link.STL" />
      </geometry>
    </collision>
  </link>
  <joint
    name="chassis_wheel1_joint"
    type="continuous">
    <origin
      xyz="0.2912 0.00 0.043" 
      rpy="0 0 1.5707963267949" />
    <parent
      link="chassis_base_link" />
    <child
      link="chassis_wheel1_link" />
    <axis
      xyz="0 1 0" />
  </joint>


  <link
    name="chassis_wheel2_link">
    <inertial>
      <origin
        xyz="0.0 0.0 0.0"
        rpy="0 0 0" />
      <mass
        value="0.225" />
      <inertia
        ixx="0.000250170368181162"
        ixy="0.0"
        ixz="0.0"
        iyy="0.000453682328977403"
        iyz="0.0"
        izz="0.000250170247771797" />
    </inertial>
    <visual>
      <origin
        xyz="0 0 0"
        rpy="0 0 0" />
      <geometry>
        <mesh
          filename="meshes/chassis/chassis_wheel2_link.STL" />
      </geometry>
      <material
        name="DarkGrey">
      </material>
    </visual>
    <collision>
      <origin
        xyz="0 0 0"
        rpy="0 0 0" />
      <geometry>
        <mesh
          filename="meshes/chassis/chassis_wheel2_link.STL" />
      </geometry>
    </collision>
  </link>
  <joint
    name="chassis_wheel2_joint"
    type="continuous">
    <origin
      xyz="-0.1456 0.2521866 0.043"
      rpy="0 0 -2.61799387799149" />
    <parent
      link="chassis_base_link" />
    <child
      link="chassis_wheel2_link" />
    <axis
      xyz="0 1 0" />
  </joint>


  <link
    name="chassis_wheel3_link">
    <inertial>
      <origin
        xyz="0 0 0"
        rpy="0 0 0" />
      <mass
        value="0.225" />
      <inertia
        ixx="0.000250170356887716"
        ixy="0.0"
        ixz="0.0"
        iyy="0.000453682330899294"
        iyz="0.0"
        izz="0.000250170254974086" />
    </inertial>
    <visual>
      <origin
        xyz="0 0 0"
        rpy="0 0 0" />
      <geometry>
        <mesh
          filename="meshes/chassis/chassis_wheel3_link.STL" />
      </geometry>
      <material
        name="DarkGrey">
      </material>
    </visual>
    <collision>
      <origin
        xyz="0 0 0"
        rpy="0 0 0" />
      <geometry>
        <mesh
          filename="meshes/chassis/chassis_wheel3_link.STL" />
      </geometry>
    </collision>


  </link>
  <joint
    name="chassis_wheel3_joint"
    type="continuous">
    <origin
      xyz="-0.1456 -0.2521866 0.043"
      rpy="0 0 -0.5235987755983" />
    <parent
      link="chassis_base_link" />
    <child
      link="chassis_wheel3_link" />
    <axis
      xyz="0 1 0" />
  </joint>
  <link
    name="chassis_controller_link">
    <inertial>
      <origin
        xyz="-0.0186693330360403 -0.0297305955474186 0.00755226601975803"
        rpy="0 0 0" />
      <mass
        value="0.0007" />
      <inertia
        ixx="0.0001"
        ixy="0.0001"
        ixz="0.0001"
        iyy="0.0001"
        iyz="0.0001"
        izz="0.0001" />
    </inertial>
    <visual>
      <origin
        xyz="0 0 0"
        rpy="0 0 0" />
      <geometry>
        <mesh
          filename="meshes/chassis/chassis_controller_link.STL" />
      </geometry>
      <material
        name="PlasticBlack">
      </material>
    </visual>
    <collision>
      <origin
        xyz="0 0 0"
        rpy="0 0 0" />
      <geometry>
        <mesh
          filename="meshes/chassis/chassis_controller_link.STL" />
      </geometry>
    </collision>
  </link>
  <joint
    name="chassis_controller_joint"
    type="fixed">
    <origin
      xyz="0.0481270870349519 -0.102981937037452 0.00400000000000172"
      rpy="0 0 0" />
    <parent
      link="chassis_base_link" />
    <child
      link="chassis_controller_link" />
    <axis
      xyz="0 0 0" />
  </joint>


  <link
    name="chassis_camera_link">
    <inertial>
      <origin
        xyz="0.0 0.0 0.0"
        rpy="0 0 0" />
      <mass
        value="0.056" />
      <inertia
        ixx="0.000130802189180016"
        ixy="0.0"
        ixz="0.0"
        iyy="0.0"
        iyz="0.0"
        izz="0.000131387473788046" />
    </inertial>
    <visual>
      <origin
        xyz="0 0 0"
        rpy="0 0 0" />
      <geometry>
        <mesh
          filename="meshes/chassis/chassis_camera_link.STL" />
      </geometry>
      <material
        name="PlasticBlack">
      </material>
    </visual>
    <collision>
      <origin
        xyz="0 0 0"
        rpy="0 0 0" />
      <geometry>
        <mesh
          filename="meshes/chassis/chassis_camera_link.STL" />
      </geometry>
    </collision>
  </link>
  <joint
    name="chassis_camera_joint"
    type="fixed">
    <origin
      xyz="0.21546 0.0 0.10825"
      rpy="0 0 0" />
    <parent
      link="chassis_base_link" />
    <child
      link="chassis_camera_link" />
    <axis
      xyz="0 0 0" />
  </joint>


  <link
    name="chassis_laser_link">
    <inertial>
      <origin
        xyz="0 0 0"
        rpy="0 0 0" />
      <mass
        value="0.005" />
      <inertia
        ixx="0.0001"
        ixy="0.0001"
        ixz="0.0001"
        iyy="0.0001"
        iyz="0.0001"
        izz="0.0001" />
    </inertial>
    <visual>
      <origin
        xyz="0 0 0"
        rpy="0 0 0" />
      <geometry>
        <mesh
          filename="meshes/chassis/chassis_laser.STL" />
      </geometry>
      <material
        name="PlasticBlack">
      </material>
    </visual>
    <collision>
      <origin
        xyz="0 0 0"
        rpy="0 0 0" />
      <geometry>
        <mesh
          filename="meshes/chassis/chassis_laser.STL" />
      </geometry>
    </collision>
  </link>
  <joint
    name="chassis_laser_joint"
    type="fixed">
    <origin
      xyz="0.143995652658148 0.0 0.138056000000001"
      rpy="0 0 -3.14159265358979" />
    <parent
      link="chassis_base_link" />
    <child
      link="chassis_laser_link" />
    <axis
      xyz="0 0 0" />
  </joint>

  
<!--                                                                -->
<!-- Chassis accessorial floor (second floor for motor power supply)-->
<!--     (third floor for arm power supply and eletric poles)       -->

  <link
    name="chassis_second_floor_link">
    <inertial>
      <origin
        xyz="0 0 0"
        rpy="0 0 0" />
      <mass
        value="8.0" />
      <inertia
        ixx="0.0001"
        ixy="0.0001"
        ixz="0.0001"
        iyy="0.0001"
        iyz="0.0001"
        izz="0.0001" />
    </inertial>
    <visual>
      <origin
        xyz="0 0 0"
        rpy="0 0 0" />
      <geometry>
        <mesh
          filename="meshes/chassis/mesh_textured/MoPER_second_floor.obj" scale="0.001 0.001 0.001" />
      </geometry>
      <material
        name="Aluminium">
      </material>
    </visual>
    <collision>
      <origin
        xyz="0 0 0"
        rpy="0 0 0" />
      <geometry>
        <mesh
          filename="meshes/chassis/mesh_textured/MoPER_second_floor.obj" scale="0.001 0.001 0.001" />
      </geometry>
    </collision>
  </link>
  <joint
    name="chassis_second_floor_joint"
    type="fixed">
    <origin
      xyz="0.0 0.0 0.088"
      rpy="1.5707963267949 0 0.523598" />
    <parent
      link="chassis_base_link" />
    <child
      link="chassis_second_floor_link" />
    <axis
      xyz="0 0 0" />
  </joint>


  <link
    name="chassis_third_floor_link">
    <inertial>
      <origin
        xyz="0 0 0"
        rpy="0 0 0" />
      <mass
        value="10.0" />
      <inertia
        ixx="0.0001"
        ixy="0.0001"
        ixz="0.0001"
        iyy="0.0001"
        iyz="0.0001"
        izz="0.0001" />
    </inertial>
    <visual>
      <origin
        xyz="0 0 0"
        rpy="0 0 0" />
      <geometry>
        <mesh
          filename="meshes/chassis/mesh_textured/MoPER_third_floor.obj" scale="0.001 0.001 0.001" />
      </geometry>
      <material
        name="Aluminium">
      </material>
    </visual>
    <collision>
      <origin
        xyz="0 0 0"
        rpy="0 0 0" />
      <geometry>
        <mesh
          filename="meshes/chassis/mesh_textured/MoPER_third_floor.obj" scale="0.001 0.001 0.001" />
      </geometry>
    </collision>
  </link>
  <joint
    name="chassis_third_floor_joint"
    type="prismatic">
    <!-- the third floor is assembled with the second floor in solidworks with the same origin, thus no offset-->
    <origin
      xyz="0.0 0.0 0.0"
      rpy="0 0 0" />
    <parent 
      link="chassis_second_floor_link" />
    <child
      link="chassis_third_floor_link" />
    <axis
      xyz="0 1 0" />
    <limit
      lower="0"
      upper="0.15"
      effort="10"
      velocity="1" />
  </joint>

<!--                                        -->
<!--           PIPER robotic arm            -->
<!--                                        -->
  <link
    name="arm_base_link">
    <inertial>
      <origin 
        xyz="0 0 0.041451518036016" 
        rpy="0 0 0" />
      <mass 
        value="1.02" />
      <inertia 
        ixx="0.00267433" 
        ixy="-0.00000073" 
        ixz="-0.00017389" 
        iyy="0.00282612" 
        iyz="0.0000004" 
        izz="0.00089624" />
    </inertial>
    <visual>
      <origin
        xyz="0 0 0"
        rpy="0 0 0" />
      <geometry>
        <mesh
          filename="meshes/arm/arm_base_link.STL" />
      </geometry>
      <material name="PlasticBlack"/>
    </visual>
    <collision>
      <origin
        xyz="0 0 0"
        rpy="0 0 0" />
      <geometry>
        <mesh
          filename="meshes/arm/arm_base_link.STL" />
      </geometry>
    </collision>
  </link>
  <joint
    name="arm_base_joint"
    type="fixed">
    <origin
      xyz="0.087468 0.41836 0.0505" 
      rpy="-1.5707963267949 -0.523598 0" />
    <parent
      link="chassis_third_floor_link" />
    <child
      link="arm_base_link" />
    <axis
      xyz="0 0 0" />
  </joint>

  <link
    name="arm_link1">
    <inertial>
      <origin 
        xyz="0.000121504734057468 0.000104632162460536 -0.00438597309559853" 
        rpy="0 0 0" />
      <mass 
        value="0.71" />
      <inertia 
        ixx="0.00048916" 
        ixy="-0.00000036" 
        ixz="-0.00000224" 
        iyy="0.00040472" 
        iyz="-0.00000242" 
        izz="0.00043982" />
    </inertial>
    <visual>
      <origin
        xyz="0 0 0"
        rpy="0 0 0" />
      <geometry>
        <mesh
          filename="meshes/arm/arm_link1.STL" />
      </geometry>
      <material name="PlasticBlack"/>
    </visual>
    <collision>
      <origin
        xyz="0 0 0"
        rpy="0 0 0" />
      <geometry>
        <mesh
          filename="meshes/arm/arm_link1.STL" />
      </geometry>
    </collision>
  </link>
  <joint
    name="arm_joint1"
    type="revolute">
    <origin
      xyz="0 0 0.123"
      rpy="0 0 0" />
    <parent
      link="arm_base_link" />
    <child
      link="arm_link1" />
    <axis
      xyz="0 0 1" />
    <limit
      lower="-2.618"
      upper="2.168"
      effort="100"
      velocity="5" />
  </joint>

<link
    name="arm_link2">
    <inertial>
      <origin 
        xyz="0.198666145229743 -0.010926924140076 0.00142121714502687" 
        rpy="0 0 0" />
      <mass 
        value="1.17" />
      <inertia 
        ixx="0.00116918" 
        ixy="-0.00180037" 
        ixz="0.00025146" 
        iyy="0.06785384" 
        iyz="-0.00000455" 
        izz="0.06774489" />
    </inertial>
    <visual>
      <origin
        xyz="0 0 0"
        rpy="0 0 0" />
      <geometry>
        <mesh
          filename="meshes/arm/arm_link2.STL" />
      </geometry>
      <material name="PlasticBlack"/>
    </visual>
    <collision>
      <origin
        xyz="0 0 0"
        rpy="0 0 0" />
      <geometry>
        <mesh
          filename="meshes/arm/arm_link2.STL" />
      </geometry>
    </collision>
  </link>
  <joint
    name="arm_joint2"
    type="revolute">
    <origin
      xyz="0 0 0"
      rpy="1.5708 -0.1359 -3.1416" />
      <!-- rpy="1.5708 -0.10095-0.03490659 -3.1416" /> -->
    <parent
      link="arm_link1" />
    <child
      link="arm_link2" />
    <axis
      xyz="0 0 1" />
    <limit
      lower="0"
      upper="3.14"
      effort="100"
      velocity="5" />
  </joint>
  <link
    name="arm_link3">
    <inertial>
      <origin 
        xyz="-0.0202737662122021 -0.133914995944595 -0.000458682652737356" 
        rpy="0 0 0" />
      <mass 
        value="0.5" />
      <inertia 
        ixx="0.01361711" 
        ixy="0.00165794" 
        ixz="-0.00000048" 
        iyy="0.00045024" 
        iyz="-0.00000045" 
        izz="0.01380322" />
    </inertial>
    <visual>
      <origin
        xyz="0 0 0"
        rpy="0 0 0" />
      <geometry>
        <mesh
          filename="meshes/arm/arm_link3.STL" />
      </geometry>
      <material name="PlasticBlack"/>
    </visual>
    <collision>
      <origin
        xyz="0 0 0"
        rpy="0 0 0" />
      <geometry>
        <mesh
          filename="meshes/arm/arm_link3.STL" />
      </geometry>
    </collision>
  </link>
  <joint
    name="arm_joint3"
    type="revolute">
    <origin
      xyz="0.28503 0 0"
      rpy="0 0 -1.7939" />
      <!-- rpy="0 0 -1.759-0.03490659" /> -->
    <parent
      link="arm_link2" />
    <child
      link="arm_link3" />
    <axis
      xyz="0 0 1" />
    <limit
      lower="-2.967"
      upper="0"
      effort="100"
      velocity="5" />
  </joint>
  <link
    name="arm_link4">
    <inertial>
      <origin 
        xyz="-9.66635791618542E-05 0.000876064475651083 -0.00496880904640868" 
        rpy="0 0 0" />
      <mass 
        value="0.38" />
      <inertia 
        ixx="0.00018501" 
        ixy="0.00000054" 
        ixz="0.00000120" 
        iyy="0.00018965" 
        iyz="-0.00000841" 
        izz="0.00015484" />
    </inertial>
    <visual>
      <origin
        xyz="0 0 0"
        rpy="0 0 0" />
      <geometry>
        <mesh
          filename="meshes/arm/arm_link4.STL" />
      </geometry>
      <material name="PlasticBlack"/>
    </visual>
    <collision>
      <origin
        xyz="0 0 0"
        rpy="0 0 0" />
      <geometry>
        <mesh
          filename="meshes/arm/arm_link4.STL" />
      </geometry>
    </collision>
  </link>
  <joint
    name="arm_joint4"
    type="revolute">
    <origin
      xyz="-0.021984 -0.25075 0"
      rpy="1.5708 0 0" />
    <parent
      link="arm_link3" />
    <child
      link="arm_link4" />
    <axis
      xyz="0 0 1" />
    <limit
      lower="-1.745"
      upper="1.745"
      effort="100"
      velocity="5" />
  </joint>
  <link
    name="arm_link5">
    <inertial>
      <origin 
        xyz="-4.10554118924211E-05 -0.0566486692356075 -0.0037205791677906" 
        rpy="0 0 0" />
      <mass 
        value="0.383" />
      <inertia 
        ixx="0.00166169" 
        ixy="0.00000006" 
        ixz="-0.00000007" 
        iyy="0.00018510" 
        iyz="0.00001026" 
        izz="0.00164321" />
    </inertial>
    <visual>
      <origin
        xyz="0 0 0"
        rpy="0 0 0" />
      <geometry>
        <mesh
          filename="meshes/arm/arm_link5.STL" />
      </geometry>
      <material name="PlasticBlack"/>
    </visual>
    <collision>
      <origin
        xyz="0 0 0"
        rpy="0 0 0" />
      <geometry>
        <mesh
          filename="meshes/arm/arm_link5.STL" />
      </geometry>
    </collision>
  </link>
  <joint
    name="arm_joint5"
    type="revolute">
    <origin
      xyz="0 0 0"
      rpy="-1.5708 0 0" />
    <parent
      link="arm_link4" />
    <child
      link="arm_link5" />
    <axis
      xyz="0 0 1" />
    <limit
      lower="-1.22"
      upper="1.22"
      effort="100"
      velocity="5" />
  </joint>
  <link
    name="arm_link6">
    <inertial>
      <origin 
        xyz="-8.82590762930069E-05 9.0598378529832E-06 -0.002" 
        rpy="0 0 0" />
      <mass 
        value="0.007" />
      <inertia 
        ixx="5.73015540542155E-07" 
        ixy="-1.98305403089247E-22" 
        ixz="-7.2791893904596E-23" 
        iyy="5.73015540542155E-07" 
        iyz="-3.4146026640245E-24" 
        izz="1.06738869138926E-06" />
    </inertial>
    <visual>
      <origin
        xyz="0 0 0"
        rpy="0 0 0" />
      <geometry>
        <mesh
          filename="meshes/arm/arm_link6.STL" />
      </geometry>
      <material name="PlasticBlack"/>
    </visual>
    <collision>
      <origin
        xyz="0 0 0"
        rpy="0 0 0" />
      <geometry>
        <mesh
          filename="meshes/arm/arm_link6.STL" />
      </geometry>
    </collision>
  </link>
  <joint
    name="arm_joint6"
    type="revolute">
    <origin
      xyz="8.8259E-05 -0.091 0"
      rpy="1.5708 0 0" />
    <parent
      link="arm_link5" />
    <child
      link="arm_link6" />
    <axis
      xyz="0 0 1" />
    <limit
      lower="-2.0944"
      upper="2.0944"
      effort="100"
      velocity="3" />
  </joint>
  <link
    name="arm_gripper_base">
    <inertial>
      <origin
        xyz="-0.000183807162235591 8.05033155577911E-05 0.0321436689908876"
        rpy="0 0 0" />
      <mass
        value="0.45" />
      <inertia
        ixx="0.00092934"
        ixy="0.00000034"
        ixz="-0.00000738"
        iyy="0.00071447"
        iyz="0.00000005"
        izz="0.00039442" />
    </inertial>
    <visual>
      <origin
        xyz="0 0 0"
        rpy="0 0 0" />
      <geometry>
        <mesh
          filename="meshes/arm/arm_gripper_base_v2.STL" scale="0.001 0.001 0.001"/>
      </geometry>
      <material name="PlasticBlack"/>
    </visual>
    <collision>
      <origin
        xyz="0 0 0"
        rpy="0 0 0" />
      <geometry>
        <mesh
          filename="meshes/arm/arm_gripper_base_v2.STL" scale="0.001 0.001 0.001"/>
      </geometry>
    </collision>
  </link> 
  <joint
    name="arm_joint6_to_gripper_base"
    type="fixed">
    <origin
      xyz="0 0 0"
      rpy="0 0 0" />
    <parent
      link="arm_link6" />
    <child
      link="arm_gripper_base" />
  </joint>
    
  <link
    name="arm_grasp_base">
    <inertial>
      <origin
        xyz="-0.000183807162235591 8.05033155577911E-05 0.0321436689908876"
        rpy="0 0 0" />
      <mass
        value="0.45" />
      <inertia
        ixx="0.00092934"
        ixy="0.00000034"
        ixz="-0.00000738"
        iyy="0.00071447"
        iyz="0.00000005"
        izz="0.00039442" />
    </inertial>
  </link> 
  <joint
    name="arm_grasp_base_joint"
    type="fixed">
    <origin
      xyz="0 0 0.085"
      rpy="0 0 0" />
    <parent
      link="arm_gripper_base" />
    <child
      link="arm_grasp_base" />
  </joint>

  <link
    name="arm_cam_link">
    <inertial>
      <origin
        xyz="-0.000183807162235591 8.05033155577911E-05 0.0321436689908876"
        rpy="0 0 0" />
      <mass
        value="0.45" />
      <inertia
        ixx="0.00092934"
        ixy="0.00000034"
        ixz="-0.00000738"
        iyy="0.00071447"
        iyz="0.00000005"
        izz="0.00039442" />
    </inertial>
    <visual>
      <origin
        xyz="0 0 0"
        rpy="0 0 0" />
      <geometry>
        <mesh
          filename="meshes/chassis/mesh_obj/MoPER_cam.obj" scale="0.001 0.001 0.001"/>
      </geometry>
      <material name="Aluminium"/>
    </visual>
    <collision>
      <origin
        xyz="0 0 0"
        rpy="0 0 0" />
      <geometry>
        <mesh
          filename="meshes/chassis/mesh_obj/MoPER_cam.obj" scale="0.001 0.001 0.001"/>
      </geometry>
    </collision>
  </link> 
  <joint
    name="arm_cam_joint"
    type="fixed">
    <origin
      xyz="-0.056 0 0.048"
      rpy="1.5708 -1.5708 0" />
    <parent
      link="arm_gripper_base" />
    <child
      link="arm_cam_link" />
  </joint>

  <link
    name="arm_link7">
    <inertial>
      <origin
        xyz="0.00065123185041968 -0.0491929869131989 0.00972258769184025"
        rpy="0 0 0" />
      <mass
        value="0.025" />
      <inertia
        ixx="0.00007371"
        ixy="-0.00000113"
        ixz="0.00000021"
        iyy="0.00000781"
        iyz="-0.00001372"
        izz="0.0000747" />
    </inertial>
    <visual>
      <origin
        xyz="0 0 0"
        rpy="0 0 0" />
      <geometry>
        <mesh
          filename="meshes/arm/arm_link7.STL" />
      </geometry>
      <material name="PlasticBlack"/>
    </visual>
    <collision>
      <origin
        xyz="0 0 0"
        rpy="0 0 0" />
      <geometry>
        <mesh
          filename="meshes/arm/arm_link7.STL" />
      </geometry>
    </collision>
  </link>
  <joint
    name="arm_joint7"
    type="prismatic">
    <origin
      xyz="0 0 0.1358"
      rpy="1.5708 0 0" />
    <parent
      link="arm_gripper_base" />
    <child
      link="arm_link7" />
    <axis
      xyz="0 0 1" />
    <limit
      lower="0"
      upper="0.035"
      effort="10"
      velocity="1" />
  </joint>
  <link
    name="arm_link8">
    <inertial>
      <origin
        xyz="0.000651231850419722 -0.0491929869131991 0.00972258769184024"
        rpy="0 0 0" />
      <mass
        value="0.025" />
      <inertia
        ixx="0.00007371"
        ixy="-0.00000113"
        ixz="0.00000021"
        iyy="0.00000781"
        iyz="-0.00001372"
        izz="0.0000747" />
    </inertial>
    <visual>
      <origin
        xyz="0 0 0"
        rpy="0 0 0" />
      <geometry>
        <mesh
          filename="meshes/arm/arm_link8.STL" />
      </geometry>
      <material name="PlasticBlack"/>
    </visual>
    <collision>
      <origin
        xyz="0 0 0"
        rpy="0 0 0" />
      <geometry>
        <mesh
          filename="meshes/arm/arm_link8.STL" />
      </geometry>
    </collision>
  </link>
  <joint
    name="arm_joint8"
    type="prismatic">
    <origin
      xyz="0 0 0.1358"
      rpy="1.5708 0 -3.1416" />
    <parent
      link="arm_gripper_base" />
    <child
      link="arm_link8" />
    <axis
      xyz="0 0 -1" />
    <limit
      lower="-0.035"
      upper="0"
      effort="10"
      velocity="1" />
    <dynamics
      friction="5"/> 
     
  </joint>
</robot>

</robot>
